Workbook

Sheet AHP
AC1: Hitung nilai bobot kriteria (Wi) | AJ1: Normal Matriks
A2: RESPONDEN 1 | B2: Guntur | V2: RESPONDEN 1 | W2: Matriks Perbandingan Berpasangan | AC2: Geometric mean method
V3: Kriteria | W3: Legalitas | X3: NJOP | Y3: Aksesibilitas | Z3: Kesesuaian RDTR | AA3: Penggunaan Lahan | AC3: Kriteria | AD3: Legalitas | AE3: NJOP | AF3: Aksesibilitas | AG3: Kesesuaian RDTR | AH3: Penggunaan Lahan | AJ3: Kriteria | AK3: Legalitas | AL3: NJOP | AM3: Aksesibilitas | AN3: Kesesuaian RDTR | AO3: Penggunaan Lahan | AP3: RATA-RATA
A4: Kriteria A | B4: Skala Penilaian | S4: Kriteria B | V4: Legalitas | W4: 1 | X4: 7 | Y4: 7 | Z4: 5 | AA4: 9 | AC4: Legalitas | AD4: =(W4*W23*W43*W63*W83)^(1/5) -> 1 | AE4: =(X4*X23*X43*X63*X83)^(1/5) -> 3.3197403 | AF4: =(Y4*Y23*Y43*Y63*Y83)^(1/5) -> 1.393259 | AG4: =(Z4*Z23*Z43*Z63*Z83)^(1/5) -> 3.0862536 | AH4: =(AA4*AA23*AA43*AA63*AA83)^(1/5) -> 5.0856546 | AJ4: Legalitas | AK4: =AD4/$AD$9 -> 0.39375985 | AL4: =AE4/$AE$9 -> 0.29267694 | AM4: =AF4/$AF$9 -> 0.31101038 | AN4: =AG4/$AG$9 -> 0.55466447 | AO4: =AH4/$AH$9 -> 0.37555367 | AP4: =AVERAGE(AK4:AO4) -> 0.38553306
A5: Legalitas | B5: 9 | C5: 8 | D5: 7 | E5: 6 | F5: 5 | G5: 4 | H5: 3 | I5: 2 | J5: 1 | K5: 2 | L5: 3 | M5: 4 | N5: 5 | O5: 6 | P5: 7 | Q5: 8 | R5: 9 | S5: NJOP | V5: NJOP | W5: =1/X4 -> 0.14285714 | X5: 1 | Y5: 3 | Z5: =1/X7 -> 0.33333333 | AA5: 5 | AC5: NJOP | AD5: =(W5*W24*W44*W64*W84)^(1/5) -> 0.30122839 | AE5: =(X5*X24*X44*X64*X84)^(1/5) -> 1 | AF5: =(Y5*Y24*Y44*Y64*Y84)^(1/5) -> 0.55691209 | AG5: =(Z5*Z24*Z44*Z64*Z84)^(1/5) -> 0.21444616 | AH5: =(AA5*AA24*AA44*AA64*AA84)^(1/5) -> 1.7725872 | AJ5: NJOP | AK5: =AD5/$AD$9 -> 0.11861165 | AL5: =AE5/$AE$9 -> 0.088162602 | AM5: =AF5/$AF$9 -> 0.12431676 | AN5: =AG5/$AG$9 -> 0.038540472 | AO5: =AH5/$AH$9 -> 0.13089792 | AP5: =AVERAGE(AK5:AO5) -> 0.10010588
A6: Legalitas | B6: 9 | C6: 8 | D6: 7 | E6: 6 | F6: 5 | G6: 4 | H6: 3 | I6: 2 | J6: 1 | K6: 2 | L6: 3 | M6: 4 | N6: 5 | O6: 6 | P6: 7 | Q6: 8 | R6: 9 | S6: Aksesibilitas | V6: Aksesibilitas | W6: =1/Y4 -> 0.14285714 | X6: =1/Y5 -> 0.33333333 | Y6: 1 | Z6: 5 | AA6: 3 | AC6: Aksesibilitas | AD6: =(W6*W25*W45*W65*W85)^(1/5) -> 0.71774163 | AE6: =(X6*X25*X45*X65*X85)^(1/5) -> 1.7956155 | AF6: =(Y6*Y25*Y45*Y65*Y85)^(1/5) -> 1 | AG6: =(Z6*Z25*Z45*Z65*Z85)^(1/5) -> 1 | AH6: =(AA6*AA25*AA45*AA65*AA85)^(1/5) -> 1.888175 | AJ6: Aksesibilitas | AK6: =AD6/$AD$9 -> 0.28261784 | AL6: =AE6/$AE$9 -> 0.15830614 | AM6: =AF6/$AF$9 -> 0.2232251 | AN6: =AG6/$AG$9 -> 0.17972097 | AO6: =AH6/$AH$9 -> 0.13943359 | AP6: =AVERAGE(AK6:AO6) -> 0.19666073
A7: Legalitas | B7: 9 | C7: 8 | D7: 7 | E7: 6 | F7: 5 | G7: 4 | H7: 3 | I7: 2 | J7: 1 | K7: 2 | L7: 3 | M7: 4 | N7: 5 | O7: 6 | P7: 7 | Q7: 8 | R7: 9 | S7: Kesesuaian RDTR | V7: Kesesuaian RDTR | W7: =1/Z4 -> 0.2 | X7: 3 | Y7: =1/Z6 -> 0.2 | Z7: 1 | AA7: 7 | AC7: Kesesuaian RDTR | AD7: =(W7*W26*W46*W66*W86)^(1/5) -> 0.32401745 | AE7: =(X7*X26*X46*X66*X86)^(1/5) -> 4.6631751 | AF7: =(Y7*Y26*Y46*Y66*Y86)^(1/5) -> 1 | AG7: =(Z7*Z26*Z46*Z66*Z86)^(1/5) -> 1 | AH7: =(AA7*AA26*AA46*AA66*AA86)^(1/5) -> 3.795335 | AJ7: Kesesuaian RDTR | AK7: =AD7/$AD$9 -> 0.12758506 | AL7: =AE7/$AE$9 -> 0.41111764 | AM7: =AF7/$AF$9 -> 0.2232251 | AN7: =AG7/$AG$9 -> 0.17972097 | AO7: =AH7/$AH$9 -> 0.28026913 | AP7: =AVERAGE(AK7:AO7) -> 0.24438358
A8: Legalitas | B8: 9 | C8: 8 | D8: 7 | E8: 6 | F8: 5 | G8: 4 | H8: 3 | I8: 2 | J8: 1 | K8: 2 | L8: 3 | M8: 4 | N8: 5 | O8: 6 | P8: 7 | Q8: 8 | R8: 9 | S8: Penggunaan Lahan | V8: Penggunaan Lahan | W8: =1/AA4 -> 0.11111111 | X8: =1/AA5 -> 0.2 | Y8: =1/AA6 -> 0.33333333 | Z8: =1/AA7 -> 0.14285714 | AA8: 1 | AC8: Penggunaan Lahan | AD8: =(W8*W27*W47*W67*W87)^(1/5) -> 0.19663152 | AE8: =(X8*X27*X47*X67*X87)^(1/5) -> 0.56414714 | AF8: =(Y8*Y27*Y47*Y67*Y87)^(1/5) -> 0.52961192 | AG8: =(Z8*Z27*Z47*Z67*Z87)^(1/5) -> 0.26348135 | AH8: =(AA8*AA27*AA47*AA67*AA87)^(1/5) -> 1 | AJ8: Penggunaan Lahan | AK8: =AD8/$AD$9 -> 0.077425599 | AL8: =AE8/$AE$9 -> 0.049736679 | AM8: =AF8/$AF$9 -> 0.11822267 | AN8: =AG8/$AG$9 -> 0.047353124 | AO8: =AH8/$AH$9 -> 0.07384569 | AP8: =AVERAGE(AK8:AO8) -> 0.073316753
A9: NJOP | B9: 9 | C9: 8 | D9: 7 | E9: 6 | F9: 5 | G9: 4 | H9: 3 | I9: 2 | J9: 1 | K9: 2 | L9: 3 | M9: 4 | N9: 5 | O9: 6 | P9: 7 | Q9: 8 | R9: 9 | S9: Aksesibilitas | AC9: TOTAL | AD9: =SUM(AD4:AD8) -> 2.539619 | AE9: =SUM(AE4:AE8) -> 11.342678 | AF9: =SUM(AF4:AF8) -> 4.479783 | AG9: =SUM(AG4:AG8) -> 5.5641811 | AH9: =SUM(AH4:AH8) -> 13.541752 | AJ9: EIGEN VECTOR | AP9: =SUM(AP4:AP8) -> 1
A10: NJOP | B10: 9 | C10: 8 | D10: 7 | E10: 6 | F10: 5 | G10: 4 | H10: 3 | I10: 2 | J10: 1 | K10: 2 | L10: 3 | M10: 4 | N10: 5 | O10: 6 | P10: 7 | Q10: 8 | R10: 9 | S10: Kesesuaian RDTR
A11: NJOP | B11: 9 | C11: 8 | D11: 7 | E11: 6 | F11: 5 | G11: 4 | H11: 3 | I11: 2 | J11: 1 | K11: 2 | L11: 3 | M11: 4 | N11: 5 | O11: 6 | P11: 7 | Q11: 8 | R11: 9 | S11: Penggunaan Lahan | AR11: AW | AV11: λi
A12: Aksesibilitas | B12: 9 | C12: 8 | D12: 7 | E12: 6 | F12: 5 | G12: 4 | H12: 3 | I12: 2 | J12: 1 | K12: 2 | L12: 3 | M12: 4 | N12: 5 | O12: 6 | P12: 7 | Q12: 8 | R12: 9 | S12: Kesesuaian RDTR | AD12: =AD4 -> 1 | AE12: =AE4 -> 3.3197403 | AF12: =AF4 -> 1.393259 | AG12: =AG4 -> 3.0862536 | AH12: =AH4 -> 5.0856546 | AJ12: =AP4 -> 0.38553306 | AL12: =AD12*$AJ$12 -> 0.38553306 | AM12: =AE12*$AJ$13 -> 0.33232552 | AN12: =AF12*$AJ$14 -> 0.27399933 | AO12: =AG12*$AJ$15 -> 0.7542297 | AP12: =AH12*$AJ$16 -> 0.37286368 | AR12: =SUM(AL12:AP12) -> 2.1189513 | AT12: =AP4 -> 0.38553306 | AV12: =AR12/AT12 -> 5.4961597 | AX12: λ max | AY12: =AVERAGE(AV12:AV16) -> 5.2615061
A13: Aksesibilitas | B13: 9 | C13: 8 | D13: 7 | E13: 6 | F13: 5 | G13: 4 | H13: 3 | I13: 2 | J13: 1 | K13: 2 | L13: 3 | M13: 4 | N13: 5 | O13: 6 | P13: 7 | Q13: 8 | R13: 9 | S13: Penggunaan Lahan | AD13: =AD5 -> 0.30122839 | AE13: =AE5 -> 1 | AF13: =AF5 -> 0.55691209 | AG13: =AG5 -> 0.21444616 | AH13: =AH5 -> 1.7725872 | AJ13: =AP5 -> 0.10010588 | AL13: =AD13*$AJ$12 -> 0.1161335 | AM13: =AE13*$AJ$13 -> 0.10010588 | AN13: =AF13*$AJ$14 -> 0.10952274 | AO13: =AG13*$AJ$15 -> 0.052407121 | AP13: =AH13*$AJ$16 -> 0.12996034 | AR13: =SUM(AL13:AP13) -> 0.50812958 | AT13: =AP5 -> 0.10010588 | AV13: =AR13/AT13 -> 5.0759214 | AX13: CI | AY13: =(AY12-5)/(5-1) -> 0.06537652
A14: Kesesuaian RDTR | B14: 9 | C14: 8 | D14: 7 | E14: 6 | F14: 5 | G14: 4 | H14: 3 | I14: 2 | J14: 1 | K14: 2 | L14: 3 | M14: 4 | N14: 5 | O14: 6 | P14: 7 | Q14: 8 | R14: 9 | S14: Penggunaan Lahan | AD14: =AD6 -> 0.71774163 | AE14: =AE6 -> 1.7956155 | AF14: =AF6 -> 1 | AG14: =AG6 -> 1 | AH14: =AH6 -> 1.888175 | AJ14: =AP6 -> 0.19666073 | AL14: =AD14*$AJ$12 -> 0.27671313 | AM14: =AE14*$AJ$13 -> 0.17975167 | AN14: =AF14*$AJ$14 -> 0.19666073 | AO14: =AG14*$AJ$15 -> 0.24438358 | AP14: =AH14*$AJ$16 -> 0.13843486 | AQ14: = | AR14: =SUM(AL14:AP14) -> 1.035944 | AS14: / | AT14: =AP6 -> 0.19666073 | AU14: = | AV14: =AR14/AT14 -> 5.2676708 | AX14: RI | AY14: 1.12
AD15: =AD7 -> 0.32401745 | AE15: =AE7 -> 4.6631751 | AF15: =AF7 -> 1 | AG15: =AG7 -> 1 | AH15: =AH7 -> 3.795335 | AJ15: =AP7 -> 0.24438358 | AL15: =AD15*$AJ$12 -> 0.12491944 | AM15: =AE15*$AJ$13 -> 0.46681124 | AN15: =AF15*$AJ$14 -> 0.19666073 | AO15: =AG15*$AJ$15 -> 0.24438358 | AP15: =AH15*$AJ$16 -> 0.27826164 | AR15: =SUM(AL15:AP15) -> 1.3110366 | AT15: =AP7 -> 0.24438358 | AV15: =AR15/AT15 -> 5.3646674 | AX15: CR | AY15: =AY13/1.12 -> 0.058371893
AD16: =AD8 -> 0.19663152 | AE16: =AE8 -> 0.56414714 | AF16: =AF8 -> 0.52961192 | AG16: =AG8 -> 0.26348135 | AH16: =AH8 -> 1 | AJ16: =AP8 -> 0.073316753 | AL16: =AD16*$AJ$12 -> 0.075807952 | AM16: =AE16*$AJ$13 -> 0.056474446 | AN16: =AF16*$AJ$14 -> 0.10415386 | AO16: =AG16*$AJ$15 -> 0.064390517 | AP16: =AH16*$AJ$16 -> 0.073316753 | AR16: =SUM(AL16:AP16) -> 0.37414353 | AT16: =AP8 -> 0.073316753 | AV16: =AR16/AT16 -> 5.1031111 | AX16: CR <0,1 | AY16: konsisten
AX18: Kriteria | AY18: BOBOT
AX19: Legalitas | AY19: =AP4 -> 0.38553306
AX20: NJOP | AY20: =AP5 -> 0.10010588
A21: RESPONDEN 2 | B21: Saha | V21: RESPONDEN 2 | AX21: Aksesibilitas | AY21: =AP6 -> 0.19666073
V22: Kriteria | W22: Legalitas | X22: NJOP | Y22: Aksesibilitas | Z22: Kesesuaian RDTR | AA22: Penggunaan Lahan | AX22: Kesesuaian RDTR | AY22: =AP7 -> 0.24438358
A23: Kriteria A | B23: Skala Penilaian | S23: Kriteria B | V23: Legalitas | W23: 1 | X23: 4 | Y23: 5 | Z23: 2 | AA23: 3 | AX23: Penggunaan Lahan | AY23: =AP8 -> 0.073316753
A24: Legalitas | B24: 9 | C24: 8 | D24: 7 | E24: 6 | F24: 5 | G24: 4 | H24: 3 | I24: 2 | J24: 1 | K24: 2 | L24: 3 | M24: 4 | N24: 5 | O24: 6 | P24: 7 | Q24: 8 | R24: 9 | S24: NJOP | V24: NJOP | W24: =1/X23 -> 0.25 | X24: 1 | Y24: 2 | Z24: =1/X26 -> 0.33333333 | AA24: =1/X27 -> 0.5 | AX24: TOTAL | AY24: =SUM(AY19:AY23) -> 1
A25: Legalitas | B25: 9 | C25: 8 | D25: 7 | E25: 6 | F25: 5 | G25: 4 | H25: 3 | I25: 2 | J25: 1 | K25: 2 | L25: 3 | M25: 4 | N25: 5 | O25: 6 | P25: 7 | Q25: 8 | R25: 9 | S25: Aksesibilitas | V25: Aksesibilitas | W25: =1/Y23 -> 0.2 | X25: =1/Y24 -> 0.5 | Y25: 1 | Z25: =1/Y26 -> 0.25 | AA25: =1/Y27 -> 0.33333333
A26: Legalitas | B26: 9 | C26: 8 | D26: 7 | E26: 6 | F26: 5 | G26: 4 | H26: 3 | I26: 2 | J26: 1 | K26: 2 | L26: 3 | M26: 4 | N26: 5 | O26: 6 | P26: 7 | Q26: 8 | R26: 9 | S26: Kesesuaian RDTR | V26: Kesesuaian RDTR | W26: =1/Z23 -> 0.5 | X26: 3 | Y26: 4 | Z26: 1 | AA26: =1/Z27 -> 0.5
A27: Legalitas | B27: 9 | C27: 8 | D27: 7 | E27: 6 | F27: 5 | G27: 4 | H27: 3 | I27: 2 | J27: 1 | K27: 2 | L27: 3 | M27: 4 | N27: 5 | O27: 6 | P27: 7 | Q27: 8 | R27: 9 | S27: Penggunaan Lahan | V27: Penggunaan Lahan | W27: =1/AA23 -> 0.33333333 | X27: 2 | Y27: 3 | Z27: 2 | AA27: 1
A28: NJOP | B28: 9 | C28: 8 | D28: 7 | E28: 6 | F28: 5 | G28: 4 | H28: 3 | I28: 2 | J28: 1 | K28: 2 | L28: 3 | M28: 4 | N28: 5 | O28: 6 | P28: 7 | Q28: 8 | R28: 9 | S28: Aksesibilitas
A29: NJOP | B29: 9 | C29: 8 | D29: 7 | E29: 6 | F29: 5 | G29: 4 | H29: 3 | I29: 2 | J29: 1 | K29: 2 | L29: 3 | M29: 4 | N29: 5 | O29: 6 | P29: 7 | Q29: 8 | R29: 9 | S29: Kesesuaian RDTR
A30: NJOP | B30: 9 | C30: 8 | D30: 7 | E30: 6 | F30: 5 | G30: 4 | H30: 3 | I30: 2 | J30: 1 | K30: 2 | L30: 3 | M30: 4 | N30: 5 | O30: 6 | P30: 7 | Q30: 8 | R30: 9 | S30: Penggunaan Lahan
A31: Aksesibilitas | B31: 9 | C31: 8 | D31: 7 | E31: 6 | F31: 5 | G31: 4 | H31: 3 | I31: 2 | J31: 1 | K31: 2 | L31: 3 | M31: 4 | N31: 5 | O31: 6 | P31: 7 | Q31: 8 | R31: 9 | S31: Kesesuaian RDTR
A32: Aksesibilitas | B32: 9 | C32: 8 | D32: 7 | E32: 6 | F32: 5 | G32: 4 | H32: 3 | I32: 2 | J32: 1 | K32: 2 | L32: 3 | M32: 4 | N32: 5 | O32: 6 | P32: 7 | Q32: 8 | R32: 9 | S32: Penggunaan Lahan
A33: Kesesuaian RDTR | B33: 9 | C33: 8 | D33: 7 | E33: 6 | F33: 5 | G33: 4 | H33: 3 | I33: 2 | J33: 1 | K33: 2 | L33: 3 | M33: 4 | N33: 5 | O33: 6 | P33: 7 | Q33: 8 | R33: 9 | S33: Penggunaan Lahan
A41: RESPONDEN 3 | B41: Yuda | V41: RESPONDEN 3
V42: Kriteria | W42: Legalitas | X42: NJOP | Y42: Aksesibilitas | Z42: Kesesuaian RDTR | AA42: Penggunaan Lahan
A43: Kriteria A | B43: Skala Penilaian | S43: Kriteria B | V43: Legalitas | W43: 1 | X43: 8 | Y43: 3 | Z43: 4 | AA43: 6
A44: Legalitas | B44: 9 | C44: 8 | D44: 7 | E44: 6 | F44: 5 | G44: 4 | H44: 3 | I44: 2 | J44: 1 | K44: 2 | L44: 3 | M44: 4 | N44: 5 | O44: 6 | P44: 7 | Q44: 8 | R44: 9 | S44: NJOP | V44: NJOP | W44: =1/X43 -> 0.125 | X44: 1 | Y44: =1/X45 -> 0.25 | Z44: =1/X46 -> 0.2 | AA44: 3
A45: Legalitas | B45: 9 | C45: 8 | D45: 7 | E45: 6 | F45: 5 | G45: 4 | H45: 3 | I45: 2 | J45: 1 | K45: 2 | L45: 3 | M45: 4 | N45: 5 | O45: 6 | P45: 7 | Q45: 8 | R45: 9 | S45: Aksesibilitas | V45: Aksesibilitas | W45: =1/Y43 -> 0.33333333 | X45: 4 | Y45: 1 | Z45: 4 | AA45: 6
A46: Legalitas | B46: 9 | C46: 8 | D46: 7 | E46: 6 | F46: 5 | G46: 4 | H46: 3 | I46: 2 | J46: 1 | K46: 2 | L46: 3 | M46: 4 | N46: 5 | O46: 6 | P46: 7 | Q46: 8 | R46: 9 | S46: Kesesuaian RDTR | V46: Kesesuaian RDTR | W46: =1/Z43 -> 0.25 | X46: 5 | Y46: =1/Z45 -> 0.25 | Z46: 1 | AA46: 5
A47: Legalitas | B47: 9 | C47: 8 | D47: 7 | E47: 6 | F47: 5 | G47: 4 | H47: 3 | I47: 2 | J47: 1 | K47: 2 | L47: 3 | M47: 4 | N47: 5 | O47: 6 | P47: 7 | Q47: 8 | R47: 9 | S47: Penggunaan Lahan | V47: Penggunaan Lahan | W47: =1/AA43 -> 0.16666667 | X47: =1/AA44 -> 0.33333333 | Y47: =1/AA45 -> 0.16666667 | Z47: =1/AA46 -> 0.2 | AA47: 1
A48: NJOP | B48: 9 | C48: 8 | D48: 7 | E48: 6 | F48: 5 | G48: 4 | H48: 3 | I48: 2 | J48: 1 | K48: 2 | L48: 3 | M48: 4 | N48: 5 | O48: 6 | P48: 7 | Q48: 8 | R48: 9 | S48: Aksesibilitas
...

Sheet Ringkasan
A1: Bobot AHP (gabungan 5 responden, geometric mean)
A3: Kriteria | B3: Bobot
A4: Legalitas | B4: =AHP!AP4 -> 0.38553306
A5: NJOP | B5: =AHP!AP5 -> 0.10010588
A6: Aksesibilitas | B6: =AHP!AP6 -> 0.19666073
A7: Kesesuaian RDTR | B7: =AHP!AP7 -> 0.24438358
A8: Penggunaan Lahan | B8: =AHP!AP8 -> 0.073316753
A9: TOTAL | B9: =SUM(B4:B8) -> 1
A11: λ max | B11: =AHP!AY12 -> 5.2615061
A12: CI | B12: =AHP!AY13 -> 0.06537652
A13: CR (gabungan) | B13: =AHP!AY15 -> 0.058371893
A14: Keterangan | B14: =IF(AHP!AY15<0.1,"konsisten","tidak konsisten") -> konsisten
A16: Konsistensi per responden (nilai hasil hitung; RI n=5 = 1,12)
A17: Responden | B17: Legalitas | C17: NJOP | D17: Aksesibilitas | E17: Kesesuaian RDTR | F17: Penggunaan Lahan | G17: λ max | H17: CI | I17: CR | J17: Keterangan
A18: Guntur | B18: 0.5272 | C18: 0.1331 | D18: 0.1522 | E18: 0.154 | F18: 0.0337 | G18: 6.5351 | H18: 0.3838 | I18: 0.343 | J18: tidak konsisten (CR > 0,1)
A19: Saha | B19: 0.4146 | C19: 0.0983 | D19: 0.0618 | E19: 0.2088 | F19: 0.2164 | G19: 5.1954 | H19: 0.0489 | I19: 0.044 | J19: konsisten
A20: Yuda | B20: 0.4648 | C20: 0.0678 | D20: 0.2643 | E20: 0.1608 | F20: 0.0423 | G20: 5.5422 | H20: 0.1356 | I20: 0.121 | J20: tidak konsisten (CR > 0,1)
A21: Sintia | B21: 0.224 | C21: 0.0343 | D21: 0.26 | E21: 0.4198 | F21: 0.062 | G21: 6.1189 | H21: 0.2797 | I21: 0.25 | J21: tidak konsisten (CR > 0,1)
A22: Edsa | B22: 0.2533 | C22: 0.1884 | D22: 0.2589 | E22: 0.222 | F22: 0.0774 | G22: 9.5103 | H22: 1.1276 | I22: 1.007 | J22: tidak konsisten (CR > 0,1)

Sheet Catatan Perbaikan
A1: Perbaikan dari file asli (sel diberi warna kuning di sheet AHP):
A2: 1. Label hasil bobot (AC4:AC8, AJ4:AJ8, AX19:AX23) tertulis Kemiringan Lereng, Rawan Bencana, Katersediaan Air, Kondisi Drainase. Diganti menjadi Legalitas, NJOP, Aksesibilitas, Kesesuaian RDTR, Penggunaan Lahan.
A3: 2. Rata-rata normalisasi (AP4:AP8) semula =AVERAGE(AK:AN) sehingga kolom Penggunaan Lahan (AO) tidak ikut. Diubah menjadi =AVERAGE(AK:AO).
A4: 3. Salah ketik 'Kesesuaia RDTR' dibetulkan.
A5: 4. Sheet Ringkasan ditambahkan: bobot akhir, CR gabungan, dan CR per responden.
A6: Matriks perbandingan responden dan rumus lain tidak diubah.
